http://127.0.0.1:80/api/v0/insert?rid=8167293698&name=ADaDadas&ip=1.1.1.1

################################

http://127.0.0.1:80//api/v1/user/8167293698


################################

http://127.0.0.1:80/api/v1/user/exist/8167293698


################################

http://127.0.0.1:80/api/v0/user/8167293698

################################

https://socialclub.rockstargames.com/member/xeneht


################################

http://localhost:80/api/v0/insert?key=asdasdasd?rid=213577756&name=ikolique5&ip=109.14.158.73&note=Normal+player.&modder=0



[2022-11-10 20:38:10,268] ERROR in app: Exception on /api/v0/insert [GET]
Traceback (most recent call last):
  File "C:\Users\parae\AppData\Local\Programs\Python\Python311\Lib\site-packages\flask\app.py", line 2525, in wsgi_app
    response = self.full_dispatch_request()
               ^^^^^^^^^^^^^^^^^^^^^^^^^^^^
  File "C:\Users\parae\AppData\Local\Programs\Python\Python311\Lib\site-packages\flask\app.py", line 1822, in full_dispatch_request
    rv = self.handle_user_exception(e)
         ^^^^^^^^^^^^^^^^^^^^^^^^^^^^^
  File "C:\Users\parae\AppData\Local\Programs\Python\Python311\Lib\site-packages\flask\app.py", line 1820, in full_dispatch_request
    rv = self.dispatch_request()
         ^^^^^^^^^^^^^^^^^^^^^^^
  File "C:\Users\parae\AppData\Local\Programs\Python\Python311\Lib\site-packages\flask\app.py", line 1796, in dispatch_request
    return self.ensure_sync(self.view_functions[rule.endpoint])(**view_args)
           ^^^^^^^^^^^^^^^^^^^^^^^^^^^^^^^^^^^^^^^^^^^^^^^^^^^^^^^^^^^^^^^^^
  File "C:\Users\parae\AppData\Local\Programs\Python\Python311\Lib\site-packages\flask_limiter\extension.py", line 1152, in __inner
    R, flask.current_app.ensure_sync(cast(Callable[P, R], obj))(*a, **k)
       ^^^^^^^^^^^^^^^^^^^^^^^^^^^^^^^^^^^^^^^^^^^^^^^^^^^^^^^^^^^^^^^^^
  File "D:\asdsadsa\GitHub\FutureBlacklist\rest-api\main.py", line 147, in add_user
    if (not check_user_key(key)): # Check uploader key
            ^^^^^^^^^^^^^^^^^^^
  File "D:\asdsadsa\GitHub\FutureBlacklist\rest-api\main.py", line 77, in check_user_key
    data = db.execute(f"SELECT * FROM USER WHERE key_auth={key}")
           ^^^^^^^^^^^^^^^^^^^^^^^^^^^^^^^^^^^^^^^^^^^^^^^^^^^^^^
sqlite3.OperationalError: near "?": syntax error